Traceback (most recent call last):
  File "/srv/apps/danny/miniconda3/envs/localsgd/lib/python3.11/site-packages/urllib3/connection.py", line 198, in _new_conn
    sock = connection.create_connection(
           ^^^^^^^^^^^^^^^^^^^^^^^^^^^^^
  File "/srv/apps/danny/miniconda3/envs/localsgd/lib/python3.11/site-packages/urllib3/util/connection.py", line 85, in create_connection
    raise err
  File "/srv/apps/danny/miniconda3/envs/localsgd/lib/python3.11/site-packages/urllib3/util/connection.py", line 73, in create_connection
    sock.connect(sa)
OSError: [Errno 101] Network is unreachable

The above exception was the direct cause of the following exception:

Traceback (most recent call last):
  File "/srv/apps/danny/miniconda3/envs/localsgd/lib/python3.11/site-packages/urllib3/connectionpool.py", line 787, in urlopen
    response = self._make_request(
               ^^^^^^^^^^^^^^^^^^^
  File "/srv/apps/danny/miniconda3/envs/localsgd/lib/python3.11/site-packages/urllib3/connectionpool.py", line 488, in _make_request
    raise new_e
  File "/srv/apps/danny/miniconda3/envs/localsgd/lib/python3.11/site-packages/urllib3/connectionpool.py", line 464, in _make_request
    self._validate_conn(conn)
  File "/srv/apps/danny/miniconda3/envs/localsgd/lib/python3.11/site-packages/urllib3/connectionpool.py", line 1093, in _validate_conn
    conn.connect()
  File "/srv/apps/danny/miniconda3/envs/localsgd/lib/python3.11/site-packages/urllib3/connection.py", line 704, in connect
    self.sock = sock = self._new_conn()
                       ^^^^^^^^^^^^^^^^
  File "/srv/apps/danny/miniconda3/envs/localsgd/lib/python3.11/site-packages/urllib3/connection.py", line 213, in _new_conn
    raise NewConnectionError(
urllib3.exceptions.NewConnectionError: <urllib3.connection.HTTPSConnection object at 0x7f4788acc750>: Failed to establish a new connection: [Errno 101] Network is unreachable

The above exception was the direct cause of the following exception:

Traceback (most recent call last):
  File "/srv/apps/danny/miniconda3/envs/localsgd/lib/python3.11/site-packages/requests/adapters.py", line 667, in send
    resp = conn.urlopen(
           ^^^^^^^^^^^^^
  File "/srv/apps/danny/miniconda3/envs/localsgd/lib/python3.11/site-packages/urllib3/connectionpool.py", line 841, in urlopen
    retries = retries.increment(
              ^^^^^^^^^^^^^^^^^^
  File "/srv/apps/danny/miniconda3/envs/localsgd/lib/python3.11/site-packages/urllib3/util/retry.py", line 519, in increment
    raise MaxRetryError(_pool, url, reason) from reason  # type: ignore[arg-type]
    ^^^^^^^^^^^^^^^^^^^^^^^^^^^^^^^^^^^^^^^^^^^^^^^^^^^
urllib3.exceptions.MaxRetryError: HTTPSConnectionPool(host='huggingface.co', port=443): Max retries exceeded with url: /mistralai/Mistral-7B-v0.1/resolve/main/config.json (Caused by NewConnectionError('<urllib3.connection.HTTPSConnection object at 0x7f4788acc750>: Failed to establish a new connection: [Errno 101] Network is unreachable'))

During handling of the above exception, another exception occurred:

Traceback (most recent call last):
  File "/srv/apps/danny/miniconda3/envs/localsgd/lib/python3.11/site-packages/huggingface_hub/file_download.py", line 1484, in _get_metadata_or_catch_error
    metadata = get_hf_file_metadata(
               ^^^^^^^^^^^^^^^^^^^^^
  File "/srv/apps/danny/miniconda3/envs/localsgd/lib/python3.11/site-packages/huggingface_hub/utils/_validators.py", line 114, in _inner_fn
    return fn(*args, **kwargs)
           ^^^^^^^^^^^^^^^^^^^
  File "/srv/apps/danny/miniconda3/envs/localsgd/lib/python3.11/site-packages/huggingface_hub/file_download.py", line 1401, in get_hf_file_metadata
    r = _request_wrapper(
        ^^^^^^^^^^^^^^^^^
  File "/srv/apps/danny/miniconda3/envs/localsgd/lib/python3.11/site-packages/huggingface_hub/file_download.py", line 285, in _request_wrapper
    response = _request_wrapper(
               ^^^^^^^^^^^^^^^^^
  File "/srv/apps/danny/miniconda3/envs/localsgd/lib/python3.11/site-packages/huggingface_hub/file_download.py", line 308, in _request_wrapper
    response = get_session().request(method=method, url=url, **params)
               ^^^^^^^^^^^^^^^^^^^^^^^^^^^^^^^^^^^^^^^^^^^^^^^^^^^^^^^
  File "/srv/apps/danny/miniconda3/envs/localsgd/lib/python3.11/site-packages/requests/sessions.py", line 589, in request
    resp = self.send(prep, **send_kwargs)
           ^^^^^^^^^^^^^^^^^^^^^^^^^^^^^^
  File "/srv/apps/danny/miniconda3/envs/localsgd/lib/python3.11/site-packages/requests/sessions.py", line 703, in send
    r = adapter.send(request, **kwargs)
        ^^^^^^^^^^^^^^^^^^^^^^^^^^^^^^^
  File "/srv/apps/danny/miniconda3/envs/localsgd/lib/python3.11/site-packages/huggingface_hub/utils/_http.py", line 96, in send
    return super().send(request, *args, **kwargs)
           ^^^^^^^^^^^^^^^^^^^^^^^^^^^^^^^^^^^^^^
  File "/srv/apps/danny/miniconda3/envs/localsgd/lib/python3.11/site-packages/requests/adapters.py", line 700, in send
    raise ConnectionError(e, request=request)
requests.exceptions.ConnectionError: (MaxRetryError("HTTPSConnectionPool(host='huggingface.co', port=443): Max retries exceeded with url: /mistralai/Mistral-7B-v0.1/resolve/main/config.json (Caused by NewConnectionError('<urllib3.connection.HTTPSConnection object at 0x7f4788acc750>: Failed to establish a new connection: [Errno 101] Network is unreachable'))"), '(Request ID: 3eb5a427-60b2-4372-9549-d7e1988b5804)')

The above exception was the direct cause of the following exception:

Traceback (most recent call last):
  File "/srv/apps/danny/miniconda3/envs/localsgd/lib/python3.11/site-packages/transformers/utils/hub.py", line 424, in cached_files
    hf_hub_download(
  File "/srv/apps/danny/miniconda3/envs/localsgd/lib/python3.11/site-packages/huggingface_hub/utils/_validators.py", line 114, in _inner_fn
    return fn(*args, **kwargs)
           ^^^^^^^^^^^^^^^^^^^
  File "/srv/apps/danny/miniconda3/envs/localsgd/lib/python3.11/site-packages/huggingface_hub/file_download.py", line 961, in hf_hub_download
    return _hf_hub_download_to_cache_dir(
           ^^^^^^^^^^^^^^^^^^^^^^^^^^^^^^
  File "/srv/apps/danny/miniconda3/envs/localsgd/lib/python3.11/site-packages/huggingface_hub/file_download.py", line 1068, in _hf_hub_download_to_cache_dir
    _raise_on_head_call_error(head_call_error, force_download, local_files_only)
  File "/srv/apps/danny/miniconda3/envs/localsgd/lib/python3.11/site-packages/huggingface_hub/file_download.py", line 1599, in _raise_on_head_call_error
    raise LocalEntryNotFoundError(
huggingface_hub.errors.LocalEntryNotFoundError: An error happened while trying to locate the file on the Hub and we cannot find the requested files in the local cache. Please check your connection and try again or make sure your Internet connection is on.

The above exception was the direct cause of the following exception:

Traceback (most recent call last):
  File "/srv/apps/danny/torchft-main/pure_torch_diloco.py", line 298, in <module>
    main()
  File "/srv/apps/danny/torchft-main/pure_torch_diloco.py", line 115, in main
    tokenizer = AutoTokenizer.from_pretrained(
                ^^^^^^^^^^^^^^^^^^^^^^^^^^^^^^
  File "/srv/apps/danny/miniconda3/envs/localsgd/lib/python3.11/site-packages/transformers/models/auto/tokenization_auto.py", line 930, in from_pretrained
    config = AutoConfig.from_pretrained(
             ^^^^^^^^^^^^^^^^^^^^^^^^^^^
  File "/srv/apps/danny/miniconda3/envs/localsgd/lib/python3.11/site-packages/transformers/models/auto/configuration_auto.py", line 1096, in from_pretrained
    config_dict, unused_kwargs = PretrainedConfig.get_config_dict(pretrained_model_name_or_path, **kwargs)
                                 ^^^^^^^^^^^^^^^^^^^^^^^^^^^^^^^^^^^^^^^^^^^^^^^^^^^^^^^^^^^^^^^^^^^^^^^^^
  File "/srv/apps/danny/miniconda3/envs/localsgd/lib/python3.11/site-packages/transformers/configuration_utils.py", line 594, in get_config_dict
    config_dict, kwargs = cls._get_config_dict(pretrained_model_name_or_path, **kwargs)
                          ^^^^^^^^^^^^^^^^^^^^^^^^^^^^^^^^^^^^^^^^^^^^^^^^^^^^^^^^^^^^^
  File "/srv/apps/danny/miniconda3/envs/localsgd/lib/python3.11/site-packages/transformers/configuration_utils.py", line 653, in _get_config_dict
    resolved_config_file = cached_file(
                           ^^^^^^^^^^^^
  File "/srv/apps/danny/miniconda3/envs/localsgd/lib/python3.11/site-packages/transformers/utils/hub.py", line 266, in cached_file
    file = cached_files(path_or_repo_id=path_or_repo_id, filenames=[filename], **kwargs)
           ^^^^^^^^^^^^^^^^^^^^^^^^^^^^^^^^^^^^^^^^^^^^^^^^^^^^^^^^^^^^^^^^^^^^^^^^^^^^^
  File "/srv/apps/danny/miniconda3/envs/localsgd/lib/python3.11/site-packages/transformers/utils/hub.py", line 491, in cached_files
    raise EnvironmentError(
OSError: We couldn't connect to 'https://huggingface.co' to load the files, and couldn't find them in the cached files.
Checkout your internet connection or see how to run the library in offline mode at 'https://huggingface.co/docs/transformers/installation#offline-mode'.
